[2023-08-03T14:54:56.329-0500] {taskinstance.py:1103} INFO - Dependencies all met for dep_context=non-requeueable deps ti=<TaskInstance: 6.2-monitoring.tarea4 scheduled__2022-01-01T00:00:00+00:00 [queued]>
[2023-08-03T14:54:56.382-0500] {taskinstance.py:1103} INFO - Dependencies all met for dep_context=requeueable deps ti=<TaskInstance: 6.2-monitoring.tarea4 scheduled__2022-01-01T00:00:00+00:00 [queued]>
[2023-08-03T14:54:56.384-0500] {taskinstance.py:1308} INFO - Starting attempt 1 of 3
[2023-08-03T14:54:56.486-0500] {taskinstance.py:1327} INFO - Executing <Task(PythonOperator): tarea4> on 2022-01-01 00:00:00+00:00
[2023-08-03T14:54:56.521-0500] {standard_task_runner.py:57} INFO - Started process 9297 to run task
[2023-08-03T14:54:56.551-0500] {standard_task_runner.py:84} INFO - Running: ['airflow', 'tasks', 'run', '6.2-monitoring', 'tarea4', 'scheduled__2022-01-01T00:00:00+00:00', '--job-id', '948', '--raw', '--subdir', 'DAGS_FOLDER/triggerrule.py', '--cfg-path', '/tmp/tmpvmr_fie5']
[2023-08-03T14:54:56.565-0500] {standard_task_runner.py:85} INFO - Job 948: Subtask tarea4
[2023-08-03T14:54:56.850-0500] {task_command.py:410} INFO - Running <TaskInstance: 6.2-monitoring.tarea4 scheduled__2022-01-01T00:00:00+00:00 [running]> on host pop-os.localdomain
[2023-08-03T14:54:57.434-0500] {taskinstance.py:1545} INFO - Exporting env vars: AIRFLOW_CTX_DAG_OWNER='airflow' AIRFLOW_CTX_DAG_ID='6.2-monitoring' AIRFLOW_CTX_TASK_ID='tarea4' AIRFLOW_CTX_EXECUTION_DATE='2022-01-01T00:00:00+00:00' AIRFLOW_CTX_TRY_NUMBER='1' AIRFLOW_CTX_DAG_RUN_ID='scheduled__2022-01-01T00:00:00+00:00'
[2023-08-03T14:54:57.466-0500] {taskinstance.py:1824} ERROR - Task failed with exception
Traceback (most recent call last):
  File "/home/joha/anaconda3/lib/python3.10/site-packages/airflow/operators/python.py", line 181, in execute
    return_value = self.execute_callable()
  File "/home/joha/anaconda3/lib/python3.10/site-packages/airflow/operators/python.py", line 198, in execute_callable
    return self.python_callable(*self.op_args, **self.op_kwargs)
  File "/home/joha/airflow/dags/triggerrule.py", line 9, in myfunction
    raise Exception
Exception
[2023-08-03T14:54:57.511-0500] {taskinstance.py:1345} INFO - Marking task as UP_FOR_RETRY. dag_id=6.2-monitoring, task_id=tarea4, execution_date=20220101T000000, start_date=20230803T195456, end_date=20230803T195457
[2023-08-03T14:54:58.346-0500] {standard_task_runner.py:104} ERROR - Failed to execute job 948 for task tarea4 (; 9297)
[2023-08-03T14:54:58.425-0500] {local_task_job_runner.py:225} INFO - Task exited with return code 1
[2023-08-03T14:54:58.613-0500] {taskinstance.py:2653} INFO - 0 downstream tasks scheduled from follow-on schedule check
