[2023-08-03T15:15:48.535-0500] {taskinstance.py:1103} INFO - Dependencies all met for dep_context=non-requeueable deps ti=<TaskInstance: 6.2-monitoring.tarea4 scheduled__2022-01-02T00:00:00+00:00 [queued]>
[2023-08-03T15:15:48.548-0500] {taskinstance.py:1103} INFO - Dependencies all met for dep_context=requeueable deps ti=<TaskInstance: 6.2-monitoring.tarea4 scheduled__2022-01-02T00:00:00+00:00 [queued]>
[2023-08-03T15:15:48.548-0500] {taskinstance.py:1308} INFO - Starting attempt 3 of 3
[2023-08-03T15:15:48.566-0500] {taskinstance.py:1327} INFO - Executing <Task(PythonOperator): tarea4> on 2022-01-02 00:00:00+00:00
[2023-08-03T15:15:48.571-0500] {standard_task_runner.py:57} INFO - Started process 10790 to run task
[2023-08-03T15:15:48.576-0500] {standard_task_runner.py:84} INFO - Running: ['airflow', 'tasks', 'run', '6.2-monitoring', 'tarea4', 'scheduled__2022-01-02T00:00:00+00:00', '--job-id', '956', '--raw', '--subdir', 'DAGS_FOLDER/triggerrule.py', '--cfg-path', '/tmp/tmpdm0_me9s']
[2023-08-03T15:15:48.577-0500] {standard_task_runner.py:85} INFO - Job 956: Subtask tarea4
[2023-08-03T15:15:48.615-0500] {task_command.py:410} INFO - Running <TaskInstance: 6.2-monitoring.tarea4 scheduled__2022-01-02T00:00:00+00:00 [running]> on host pop-os.localdomain
[2023-08-03T15:15:48.817-0500] {taskinstance.py:1545} INFO - Exporting env vars: AIRFLOW_CTX_DAG_OWNER='airflow' AIRFLOW_CTX_DAG_ID='6.2-monitoring' AIRFLOW_CTX_TASK_ID='tarea4' AIRFLOW_CTX_EXECUTION_DATE='2022-01-02T00:00:00+00:00' AIRFLOW_CTX_TRY_NUMBER='3' AIRFLOW_CTX_DAG_RUN_ID='scheduled__2022-01-02T00:00:00+00:00'
[2023-08-03T15:15:48.818-0500] {taskinstance.py:1824} ERROR - Task failed with exception
Traceback (most recent call last):
  File "/home/joha/anaconda3/lib/python3.10/site-packages/airflow/operators/python.py", line 181, in execute
    return_value = self.execute_callable()
  File "/home/joha/anaconda3/lib/python3.10/site-packages/airflow/operators/python.py", line 198, in execute_callable
    return self.python_callable(*self.op_args, **self.op_kwargs)
  File "/home/joha/airflow/dags/triggerrule.py", line 9, in myfunction
    raise Exception
Exception
[2023-08-03T15:15:48.823-0500] {taskinstance.py:1345} INFO - Marking task as FAILED. dag_id=6.2-monitoring, task_id=tarea4, execution_date=20220102T000000, start_date=20230803T201548, end_date=20230803T201548
[2023-08-03T15:15:48.844-0500] {standard_task_runner.py:104} ERROR - Failed to execute job 956 for task tarea4 (; 10790)
[2023-08-03T15:15:48.869-0500] {local_task_job_runner.py:225} INFO - Task exited with return code 1
[2023-08-03T15:15:48.895-0500] {taskinstance.py:2653} INFO - 0 downstream tasks scheduled from follow-on schedule check
